2019-04-25 14:40:00,219 [DEBUG] Using GPU 0
2019-04-25 14:40:00,269 [DEBUG] CACHEDIR=/home/thinh/.cache/matplotlib
2019-04-25 14:40:00,272 [DEBUG] Using fontManager instance from /home/thinh/.cache/matplotlib/fontlist-v300.json
2019-04-25 14:40:00,400 [DEBUG] Loaded backend agg version unknown.
2019-04-25 14:40:07,927 [INFO] ==> VIDEO_ROOT_PATH/UCSD_ped1/testing_h5_t0/UCSD_ped1_14.h5
2019-04-25 14:40:07,927 [DEBUG] Predicting using logs/UCSD_ped1/jobs/f5846318-6990-4622-b584-ececf33a54d7/model_snapshot_e298_0.003159.h5
2019-04-25 14:40:19,929 [CRITICAL] Uncaught exception
Traceback (most recent call last):
  File "/home/thinh/Downloads/pycharm-community-2018.3.5/helpers/pydev/pydevd.py", line 1741, in <module>
    main()
  File "/home/thinh/Downloads/pycharm-community-2018.3.5/helpers/pydev/pydevd.py", line 1735, in main
    globals = debugger.run(setup['file'], None, None, is_module)
  File "/home/thinh/Downloads/pycharm-community-2018.3.5/helpers/pydev/pydevd.py", line 1135, in run
    pydev_imports.execfile(file, globals, locals)  # execute the script
  File "/home/thinh/Downloads/pycharm-community-2018.3.5/helpers/pydev/_pydev_imps/_pydev_execfile.py", line 18, in execfile
    exec(compile(contents+"\n", file, 'exec'), glob, loc)
  File "/home/thinh/github/anomaly-detection-and-localization/start_test.py", line 73, in <module>
    visualize_score=True, visualize_frame=True)
  File "/home/thinh/github/anomaly-detection-and-localization/classifier.py", line 508, in test
    t_res = t_predict(temporal_model2, X_test, 4)
  File "/home/thinh/github/anomaly-detection-and-localization/classifier.py", line 437, in t_predict
    error_arr[i+j] += (predicted_vol[i, j] - X[i, j])**2
IndexError: list index out of range
